Workbook

Sheet Profile
A1: Onboarding | B1: Category | C1: Profile question | D1: P-text | E1: Profile answer | F1: Goal tag | G1: Life moment | H1: Content tag 1 (topic) | I1: Content tag 2 (group) | J1: Profile tag | K1: web Video/reel | L1: Mobile Video/reel | M1: Notes
A2: Onboarding | B2: circumstances | C2: Who do you include in your budget? | D2: Choose everyone you feel responsible for when planning your finances. | E2: Myself | F2: goal-retirement, goal-emergency-fund | I2: group-family | J2: profile-family-myself | K2: https://videos.ctfassets.net/pmoql4aw53io/fLHvCorN4uCZI7vL13FNe/fe0f5f334c47343d9ab3728401d69eee/onb_web_benefits.mp4 | L2: retirement video
A3: Onboarding | B3: circumstances | C3: Who do you include in your budget? | D3: Choose everyone you feel responsible for when planning your finances. | E3: Spouse/partner | G3: lm-combining-finances | H3: topic-partner | I3: group-family | J3: profile-family-spouse | K3: https://videos.ctfassets.net/pmoql4aw53io/MuB3xyTncjpeIG3yDGXMN/c87d6d0b6fdd052f55bfabdb4b011cf1/onb_web_budged.mp4 | L3: Budget video
A4: Onboarding | B4: circumstances | C4: Who do you include in your budget? | D4: Choose everyone you feel responsible for when planning your finances. | E4: Kids | F4: goal-kids-education | G4: lm-growing-your-family | H4: topic-kids | I4: group-family | J4: profile-family-havekids | K4: https://videos.ctfassets.net/pmoql4aw53io/fLHvCorN4uCZI7vL13FNe/fe0f5f334c47343d9ab3728401d69eee/onb_web_benefits.mp4 | L4: retirement video
A5: Onboarding | B5: circumstances | C5: Who do you include in your budget? | D5: Choose everyone you feel responsible for when planning your finances. | E5: Extended family | H5: topic-caregiving | I5: group-family | J5: profile-family-extendedfam
A6: Onboarding | B6: circumstances | C6: Who do you include in your budget? | D6: Choose everyone you feel responsible for when planning your finances. | E6: Parents | H6: topic-caregiving | I6: group-family | J6: profile-family-agingparents | K6: https://videos.ctfassets.net/pmoql4aw53io/fLHvCorN4uCZI7vL13FNe/fe0f5f334c47343d9ab3728401d69eee/onb_web_benefits.mp4 | L6: retirement video
A7: Onboarding | B7: circumstances | C7: Who do you include in your budget? | D7: Choose everyone you feel responsible for when planning your finances. | E7: Pets | H7: topic-pets | I7: group-family | J7: profile-family-havepets
A8: Onboarding | B8: circumstances | C8: Do you rent or own your home? | D8: A home could be a house, condo, apartment, or something else -- wherever you live! | E8: Own | H8: topic-owning-home | I8: group-housing | J8: profile-property-ownhome | K8: https://videos.ctfassets.net/pmoql4aw53io/fLHvCorN4uCZI7vL13FNe/fe0f5f334c47343d9ab3728401d69eee/onb_web_benefits.mp4 | L8: benefits
A9: Onboarding | B9: circumstances | C9: Do you rent or own your home? | D9: A home could be a house, condo, apartment, or something else -- wherever you live! | E9: Rent | F9: goal-buying-a-home | H9: topic-renting | I9: group-housing | J9: profile-property-rent | K9: Buying a Home video
A10: Onboarding | B10: circumstances | C10: Do you rent or own your home? | D10: A home could be a house, condo, apartment, or something else -- wherever you live! | E10: Neither | F10: goal-buying-a-home | H10: topic-free-housing | I10: group-housing | J10: profile-property-neither | M10: https://videos.ctfassets.net/pmoql4aw53io/fLHvCorN4uCZI7vL13FNe/fe0f5f334c47343d9ab3728401d69eee/onb_web_benefits.mp4 | N10: Benefits video
A11: Onboarding | B11: priorities | C11: What are your financial priorities? | D11: We'll connect you with information and benefits to help. | E11: Budgeting | F11: goal-emergency-fund | H11: topic-budget | I11: group-how-to-save | J11: profile-priorities-budgeting | K11: https://videos.ctfassets.net/pmoql4aw53io/MuB3xyTncjpeIG3yDGXMN/c87d6d0b6fdd052f55bfabdb4b011cf1/onb_web_budged.mp4 | L11: Budget video
A12: Onboarding | B12: priorities | C12: What are your financial priorities? | D12: We'll connect you with information and benefits to help. | E12: Buying a home | F12: goal-buying-a-home | H12: topic-mortgages | I12: group-housing | J12: profile-priorities-wanthome | K12: https://videos.ctfassets.net/pmoql4aw53io/XUE1VbhOE88IWPWawhLxZ/20f0337d8957ddadfdd028699e7b66f8/onb_web_buy_home.mp4 | L12: Buy home video
A13: Onboarding | B13: priorities | C13: What are your financial priorities? | D13: We'll connect you with information and benefits to help. | E13: College fund | F13: goal-kids-education | H13: topic-529 | I13: group-how-to-save | J13: profile-priorities-collegefund
A14: Onboarding | B14: priorities | C14: What are your financial priorities? | D14: We'll connect you with information and benefits to help. | E14: Estate planning | H14: topic-estate-planning | I14: group-benefits | J14: profile-priorities-budgeting
A15: Onboarding | B15: priorities | C15: What are your financial priorities? | D15: We'll connect you with information and benefits to help. | E15: Health costs | H15: topic-health | I15: group-benefits | J15: profile-priorities-healthcost
A16: Onboarding | B16: priorities | C16: What are your financial priorities? | D16: We'll connect you with information and benefits to help. | E16: Investing | H16: topic-investing | I16: group-investing-strategies | J16: profile-priorities-investing | K16: https://videos.ctfassets.net/pmoql4aw53io/4nSxcJwGTfzy1PfjnZM4FB/9c1b4067e968ad1960ea46cd7cce7eb2/onb_web_occams.mp4 | L16: Occam's
A17: Onboarding | B17: priorities | C17: What are your financial priorities? | D17: We'll connect you with information and benefits to help. | E17: Life insurance | H17: topic-insurance | I17: group-account-types | J17: profile-priorities-lifeinsurance
A18: Onboarding | B18: priorities | C18: What are your financial priorities? | D18: We'll connect you with information and benefits to help. | E18: Managing debt | F18: goal-debt-management | H18: topic-credit-cards | I18: group-account-types | J18: profile-priorities-debtmanagement | K18: https://videos.ctfassets.net/pmoql4aw53io/6Q4vuk0UDEcJgjVrcsscBF/242e3d1465526dad0ab5cc13ba27d545/onb_web_debt.mp4 | L18: Debt video
A19: Onboarding | B19: priorities | C19: What are your financial priorities? | D19: We'll connect you with information and benefits to help. | E19: Tax planning | H19: topic-taxes | I19: group-benefits | J19: profile-priorities-taxplanning
A20: Onboarding | B20: priorities | C20: What are your financial priorities? | D20: We'll connect you with information and benefits to help. | E20: Retirement | F20: goal-retirement | H20: topic-retirement | I20: group-account-types | J20: profile-property-retirement | K20: https://videos.ctfassets.net/pmoql4aw53io/fLHvCorN4uCZI7vL13FNe/fe0f5f334c47343d9ab3728401d69eee/onb_web_benefits.mp4 | L20: Occam's
A22: Launch questions below
A23: Profile | B23: circumstances | C23: What insurance policies do you have? | D23: Select all types that you carry currently. | E23: Disability | H23: topic-insurance | I23: group-protecting-wealth | J23: profile-disability-insurance
A24: Profile | B24: circumstances | C24: What insurance policies do you have? | D24: Select all types that you carry currently. | E24: Life | H24: topic-insurance | I24: group-protecting-wealth | J24: profile-life-insurance
A25: Profile | B25: circumstances | C25: What insurance policies do you have? | D25: Select all types that you carry currently. | E25: Home | H25: topic-insurance | I25: group-protecting-wealth | J25: profile-home-insurance
A26: Profile | B26: circumstances | C26: What insurance policies do you have? | D26: Select all types that you carry currently. | E26: Renters | H26: topic-insurance | I26: group-protecting-wealth | J26: profile-renters-insurance
A27: Profile | B27: circumstances | C27: What insurance policies do you have? | D27: Select all types that you carry currently. | E27: Umbrella | H27: topic-insurance | I27: group-protecting-wealth | J27: profile-umbrella-insurance
A28: Profile | B28: circumstances | C28: What estate plans have you put in place? | D28: Select everything you've planned for your finances after death. | E28: Will | H28: topic-estate-planning | I28: group-protecting-wealth | J28: profile-will
A29: Profile | B29: circumstances | C29: What estate plans have you put in place? | D29: Select everything you've planned for your finances after death. | E29: Trust | H29: topic-estate-planning | I29: group-caregiving | J29: profile-trust
A30: Profile | B30: circumstances | C30: What estate plans have you put in place? | D30: Select everything you've planned for your finances after death. | E30: Guardianship | H30: topic-estate-planning | I30: group-protecting-wealth | J30: profile-guardianship
A31: Profile | B31: circumstances | C31: What estate plans have you put in place? | D31: Select everything you've planned for your finances after death. | E31: Beneficiaries | H31: topic-beneficiaries | I31: group-protecting-wealth | J31: profile-beneficiaries
A32: Profile | B32: preferences | C32: How often do you want to review progress on your financial goals? | D32: Choose the answer that feels right for your needs. | E32: Never | H32: topic-goals | I32: group-priorities | J32: profile-goal-progress-never
A33: Profile | B33: preferences | C33: How often do you want to review progress on your financial goals? | D33: Choose the answer that feels right for your needs. | E33: Yearly | H33: topic-goals | I33: group-priorities | J33: profile-goal-progress-yearly
A34: Profile | B34: preferences | C34: How often do you want to review progress on your financial goals? | D34: Choose the answer that feels right for your needs. | E34: Quarterly | H34: topic-goals | I34: group-priorities | J34: profile-goal-progress-quarterly
... A39: Profile | B39: confidence & clarity | C39: What’s your investment experience level? | D39: Select the best answer to describe yourself. | E39: Intermediate | H39: topic-investing | I39: group-investing-strategies | J39: profile-invest-intermediate
B40: confidence & clarity | C40: What’s your investment experience level? | D40: Select the best answer to describe yourself. | E40: Advanced | H40: topic-investing | I40: group-investing-strategies | J40: profile-invest-advanced
A41: Profile | B41: confidence & clarity | C41: What’s your investment experience level? | D41: Select the best answer to describe yourself. | E41: None | H41: topic-investing | I41: group-investing-strategies | J41: profile-invest-none
A42: Draft below
A43: Profile | C43: In managing your finances, which professionals do you collaborate with? | D43: Select all that you've used recently or in the past. | E43: Stock broker | I43: group-investing-strategies | J43: profile-investhelp-stockbroker
A44: Profile | C44: In managing your finances, which professionals do you collaborate with? | D44: Select all that you've used recently or in the past. | E44: Investment banker | I44: group-investing-strategies | J44: profile-investhelp-investmentbanker
A45: Profile | C45: In managing your finances, which professionals do you collaborate with? | D45: Select all that you've used recently or in the past. | E45: Financial planner | I45: group-investing-strategies | J45: profile-investhelp-financialadvisor
...

Sheet New Tag keys
A1: =_xlfn.CONCAT(_xlfn.CONCAT("Goal (", COUNTA(A2:A1000)), ")") -> Goal (6) | B1: =_xlfn.CONCAT(_xlfn.CONCAT("--deprecated Life Moment (", COUNTA(B2:B1000)), ")") -> --deprecated Life Moment (7) | C1: =_xlfn.CONCAT(_xlfn.CONCAT("Life Stage (", COUNTA(B2:B1000)), ")") -> Life Stage (7) | D1: =_xlfn.CONCAT(_xlfn.CONCAT("Content topics (",COUNTA(D2:D1000)),")") -> Content topics (67) | E1: =_xlfn.CONCAT(_xlfn.CONCAT("Content groups (",COUNTA(E2:E1000)),")") -> Content groups (18) | F1: =_xlfn.CONCAT(_xlfn.CONCAT("Profile (",COUNTA(F2:F1000)),")") -> Profile (37) | G1: =_xlfn.CONCAT(_xlfn.CONCAT("Level (",COUNTA(G2:G1000)),")") -> Level (3) | H1: =_xlfn.CONCAT(_xlfn.CONCAT("Class (",COUNTA(H2:H1000)),")") -> Class (3) | I1: =_xlfn.CONCAT(_xlfn.CONCAT("Collection (",COUNTA(I2:I1000)),")") -> Collection (0) | J1: Content Type
A2: goal-retirement | B2: lm-inheritance | C2: ls-early | D2: topic-401k | E2: group-priorities | F2: profile-family-myself | G2: level-basic | H2: class-low | J2: Calculator
A3: goal-emergency-fund | B3: lm-purposeful-learning | C3: ls-mid | D3: topic-529 | E3: group-account-types | F3: profile-family-spouse | G3: level-intermediate | H3: class-mid | J3: Benefit
A4: goal-debt-management | B4: lm-growing-your-family | C4: ls-late | D4: topic-bad-debt | E4: group-how-to-save | F4: profile-family-havekids | G4: level-advanced | H4: class-high | J4: Story
A5: goal-kids-education | D5: topic-beneficiaries | F5: profile-family-extendedfam
A6: goal-buying-a-home | B6: lm-combining-finances | D6: topic-benefit | E6: group-self-care | F6: profile-family-agingparents
A7: goal-buying-a-car | B7: lm-relocation | D7: topic-benefits | E7: group-investing-strategies | F7: profile-family-havepets
B8: lm-covid | D8: topic-brokerage | E8: group-markets | F8: profile-property-ownhome
B9: lm-none | D9: topic-budget | E9: group-career | F9: profile-property-rent
D10: topic-car | E10: group-monthly | F10: profile-property-neither
D11: topic-caregiving | E11: group-paven-app | F11: profile-priorities-budgeting
D12: topic-charity | E12: l | F12: profile-priorities-wanthome
D13: topic-credit-cards | E13: group-housing | F13: profile-priorities-collegefund
D14: topic-credit-score | E14: group-caregiving | F14: profile-priorities-estateplanning
D15: topic-crypto | E15: group-finwell | F15: profile-priorities-healthcost
D16: topic-debt | E16: group-protecting-wealth | F16: profile-priorities-investing
D17: topic-estate-planning | E17: group-family | F17: profile-priorities-lifeinsurance
D18: topic-family | E18: group-childfree | F18: profile-priorities-debtmanagement
D19: topic-financial-finesse | F19: profile-priorities-taxplanning
D20: topic-first-home | F20: profile-disability-insurance
D21: topic-free-housing | F21: profile-life-insurance
D22: topic-fsa | F22: profile-home-insurance
D23: topic-goals | F23: profile-renters-insurance
D24: topic-health | F24: profile-umbrella-insurance
D25: topic-hsa | F25: profile-will
D26: topic-income | F26: profile-trust
D27: topic-industries | F27: profile-guardianship
D28: topic-inflation | F28: profile-beneficiaries
D29: topic-inheritance | F29: profile-goal-progress-never
D30: topic-insurance | F30: profile-goal-progress-yearly
... D38: topic-partner | F38: profile-invest-none
D39: topic-pets
D40: topic-relocation
D41: topic-renting
D42: topic-resilience
D43: topic-retirement
D44: topic-roth-ira
D45: topic-rsus
D46: topic-savviness
D47: topic-self-care
...

Sheet Tags 2025
A1: date | B1: id | C1: title | D1: goal_tags | E1: life_moment_tags | F1: life_stage_tags | G1: content_tags | H1: group_tags | I1: Profile Builder | J1: Link to V1 | K1: Link to V2 | L1: class_tags | M1: Audit notes | N1: Tenant | O1: Link | P1: Jolene Notes
A2: 2021 Q3 | B2: TT_1.4 | C2: Ways to use your pay raise | E2: lm-purposeful-learning | F2: ls-early ls-mid ls-late | G2: topic-income, topic-savviness | H2: group-how-to-save | I2: profile-family-myself profile-priorities-budgeting | L2: class-low | M2: class-mid | N2: general/meta | O2: https://paven.io/content/article/4cLNM7gf8dHQxcynhtkuDG | P2: Not much meat there. Mentions updating budget but no link.
A3: 2021 Q3 | B3: EMF_1.1 | C3: Do I need an emergency fund? | D3: goal-emergency-fund | E3: lm-purposeful-learning | F3: ls-early ls-mid ls-late | G3: topic-resilience | H3: group-priorities, group-how-to-save | I3: profile-priorities-budgeting | J3: https://www.figma.com/design/UOXktKMNWVxBSuZJhNGdyu/Goals?node-id=3496-10081&t=d6MHhwFJ4Ajl1iXH-1 | L3: class-low | O3: https://paven.io/content/article/3XIA1q18lV1NZXHVhmUVfV | P3: Links externally to articles, some of those links are broken/missing
A4: 2021 Q4 | B4: EMF_1.2 | C4: Saving for the unknown | D4: goal-emergency-fund | E4: lm-purposeful-learning | F4: ls-early ls-mid ls-late | G4: topic-resilience | H4: group-how-to-save | I4: profile-priorities-budgeting | J4: https://www.figma.com/design/UOXktKMNWVxBSuZJhNGdyu/Goals?node-id=3496-10082&t=d6MHhwFJ4Ajl1iXH-1 | L4: class-low | O4: https://paven.io/content/article/10BCj5GYLPT2pnrmRa8G01 | P4: Seems to have issues with 1 of the graphics
A5: 2021 Q4 | B5: SFC_1.8 | C5: Get help from a College Coach | D5: goal-kids-education | G5: topic-kids-education, topic-financial-coach | I5: profile-family-havekids | J5: https://www.figma.com/design/UOXktKMNWVxBSuZJhNGdyu/Goals?node-id=3500-67995&t=d6MHhwFJ4Ajl1iXH-1 | L5: archived
A6: 2021 Q4 | B6: RET_1.10 | C6: The basics of Meta's 401(k) plan | D6: goal-retirement | F6: ls-early ls-mid ls-late | G6: topic-retirement, topic-401k | H6: group-account-types | I6: profile-priorities-investing | J6: https://www.figma.com/design/UOXktKMNWVxBSuZJhNGdyu/Goals?node-id=3506-15659&t=d6MHhwFJ4Ajl1iXH-1 | L6: class-mid | O6: https://paven.io/benefits/article/5xcJNCiEQbb4PJHJ6glj3c | P6: Mentions of 2022 2023
A7: 2021 Q4 | B7: MM_1.7 | C7: College coaching from Bright Horizons | D7: goal-kids-education | G7: group-family, topic-benefits | I7: profile-family-havekids profile-priorities-collegefund | L7: archived
A8: 2021 Q4 | B8: DEB_1.6 | C8: Get support with Lyra | D8: goal-debt-management | F8: ls-early ls-mid ls-late | G8: topic-lyra | H8: group-how-to-save | I8: profile-priorities-healthcost | J8: https://www.figma.com/design/UOXktKMNWVxBSuZJhNGdyu/Goals?node-id=3508-49770&t=d6MHhwFJ4Ajl1iXH-1 | L8: class-mid
A9: 2021 Q4 | B9: LM_RELO_1.1 | C9: Relocation 101 | E9: lm-relocation | F9: ls-early ls-mid ls-late | G9: topic-relocation | H9: group-priorities | I9: profile-priorities-debtmanagement | J9: https://www.figma.com/design/kkMh7aGZkJopf7n5lbrrpX/Life-Moments?node-id=2565-20757&t=scW7PhQJA030oT78-1 | L9: class-low | M9: Still relevant? | O9: https://paven.io/content/article/4EDqrnZqjMVLUmpzRwSjk2
A10: 2021 Q4 | B10: LM_RELO_1.2 | C10: Buying a car when relocating | D10: goal-buying-a-car | E10: lm-relocation | F10: ls-early ls-mid ls-late | G10: topic-car | H10: group-priorities | I10: profile-priorities-debtmanagement | J10: https://www.figma.com/design/kkMh7aGZkJopf7n5lbrrpX/Life-Moments?node-id=2565-23387&t=scW7PhQJA030oT78-1 | L10: class-low | M10: Still relevant? | O10: https://paven.io/content/article/7oATLbHlAL221cMeVUAoy6
A11: 2021 Q4 | B11: LM_RELO_1.3 | C11: Save for emergencies or send money home? | D11: goal-emergency-fund, goal-buying-a-home | E11: lm-growing-your-family, lm-relocation | F11: ls-early ls-mid ls-late | G11: topic-resilience | H11: group-priorities | I11: profile-goal-progress-never profile-goal-progress-yearly profile-goal-progress-quarterly profile-goal-progress-monthly profile-goal-progress-weekly profile-goal-progress-daily | J11: https://www.figma.com/design/kkMh7aGZkJopf7n5lbrrpX/Life-Moments?node-id=2565-23389&t=scW7PhQJA030oT78-1 | L11: class-low | M11: Still relevant? | O11: https://paven.io/content/article/7MiY8sNHiCZuc076FEazOe
A12: 2021 Q4 | B12: LM_RELO_1.5 | C12: Save for retirement or send money home? | D12: goal-retirement, goal-buying-a-home | E12: lm-relocation | G12: topic-resilience | H12: group-priorities | I12: profile-goal-progress-never profile-goal-progress-yearly profile-goal-progress-quarterly profile-goal-progress-monthly profile-goal-progress-weekly profile-goal-progress-daily | J12: https://www.figma.com/design/kkMh7aGZkJopf7n5lbrrpX/Life-Moments?node-id=2565-23390&t=scW7PhQJA030oT78-1 | L12: class-low | M12: Still relevant? | O12: https://paven.io/content/article/6BSnt3S9Zwu74QHDX1PhsS
A13: 2021 Q4 | B13: EMF_1.3 | C13: Where to stash emergency funds | D13: goal-emergency-fund | G13: topic-resilience | H13: group-account-types | I13: profile-priorities-debtmanagement profile-priorities-budgeting | J13: https://www.figma.com/design/UOXktKMNWVxBSuZJhNGdyu/Goals?node-id=3496-10080&t=d6MHhwFJ4Ajl1iXH-1 | L13: class-mid | O13: https://paven.io/content/article/2vcmDPcrP6hJEuqJ6Q086E
A14: 2021 Q4 | B14: EMF_1.5 | C14: Setting up automatic transfers | D14: goal-emergency-fund | G14: topic-emergency-fund, topic-automatic-transfers | H14: group-how-to-save | I14: profile-priorities-debtmanagement profile-priorities-budgeting | J14: https://www.figma.com/design/UOXktKMNWVxBSuZJhNGdyu/Goals?node-id=3496-6025&t=d6MHhwFJ4Ajl1iXH-1 | L14: class-low | N14: Old/Needs to be rewritten | O14: https://paven.io/content/article/5lKy8OxVNCgejG7EfH3fKD
A15: 2021 Q4 | B15: EMF_1.6 | C15: How to boost emergency funds | D15: goal-emergency-fund | G15: topic-resilience | H15: group-how-to-save | I15: profile-priorities-debtmanagement profile-priorities-budgeting | J15: https://www.figma.com/design/UOXktKMNWVxBSuZJhNGdyu/Goals?node-id=3496-5926&t=d6MHhwFJ4Ajl1iXH-1 | L15: class-low | N15: Can be refreshed | O15: https://paven.io/content/article/7qXkRnZzobZjwtH2EMEerV
A16: 2021 Q4 | B16: SFC_1.1 | C16: 3 reasons to start saving now | D16: goal-kids-education | G16: group-family | H16: group-priorities | I16: profile-priorities-debtmanagement profile-priorities-budgeting | J16: https://www.figma.com/design/UOXktKMNWVxBSuZJhNGdyu/Goals?node-id=3500-67988&t=d6MHhwFJ4Ajl1iXH-1 | L16: class-low | N16: Good | O16: https://paven.io/content/article/2YEbx95wNuqCh5IS2Z6Mi9
A17: 2021 Q4 | B17: SFC_1.3 | C17: Education account types | D17: goal-kids-education | G17: group-family | H17: group-account-types | I17: profile-family-havekids profile-priorities-collegefund | J17: https://www.figma.com/design/UOXktKMNWVxBSuZJhNGdyu/Goals?node-id=3500-67990&t=d6MHhwFJ4Ajl1iXH-1 | L17: class-low | O17: https://paven.io/content/article/6Y95jlQhFRWdOUFnt4Egm
A18: 2021 Q4 | B18: SFC_1.4 | C18: The 529 plan, explained | D18: goal-kids-education | G18: topic-529 | H18: group-account-types, group-how-to-save | I18: profile-family-havekids profile-priorities-collegefund | J18: https://www.figma.com/design/UOXktKMNWVxBSuZJhNGdyu/Goals?node-id=3500-67991&t=d6MHhwFJ4Ajl1iXH-1 | L18: class-low | O18: https://paven.io/content/article/5QCbiymJdeZtNQV75taLwk
A19: 2021 Q4 | B19: SFC_1.5 | C19: Using a Roth IRA to save | D19: goal-kids-education | G19: topic-roth-ira, group-how-to-save | H19: group-account-types | I19: profile-priorities-investing profile-invest-beginner profile-invest-intermediate profile-invest-advanced profile-invest-none | J19: https://www.figma.com/design/UOXktKMNWVxBSuZJhNGdyu/Goals?node-id=3500-67992&t=d6MHhwFJ4Ajl1iXH-1 | L19: class-low | O19: https://paven.io/content/article/CZcZvvvFjtJcHiHM3DzN8
A20: 2021 Q4 | B20: SFC_1.6 | C20: Using a brokerage account to save | G20: topic-brokerage | H20: group-account-types | I20: profile-priorities-investing profile-invest-beginner profile-invest-intermediate profile-invest-advanced profile-invest-none | J20: https://www.figma.com/design/UOXktKMNWVxBSuZJhNGdyu/Goals?node-id=3500-67993&t=d6MHhwFJ4Ajl1iXH-1 | L20: class-low | O20: https://paven.io/content/article/7rKjk2k5RiPMLiKRcoXrZ1
A21: 2021 Q4 | B21: SFC_1.7 | C21: Other ways to save for education | D21: goal-kids-education | G21: group-family | H21: group-how-to-save | I21: profile-family-havekids profile-priorities-collegefund | J21: https://www.figma.com/design/UOXktKMNWVxBSuZJhNGdyu/Goals?node-id=3500-67994&t=d6MHhwFJ4Ajl1iXH-1 | L21: class-low | O21: https://paven.io/content/article/6T84VV9e9fDftdKikDRksz
A22: 2021 Q4 | B22: DEB_1.1 | C22: Good debt vs bad debt | D22: goal-debt-management | G22: topic-bad-debt, group-how-to-save | H22: group-priorities | I22: profile-priorities-debtmanagement profile-priorities-budgeting | J22: https://www.figma.com/design/UOXktKMNWVxBSuZJhNGdyu/Goals?node-id=3508-49764&t=d6MHhwFJ4Ajl1iXH-1 | L22: class-mid | O22: https://paven.io/content/article/2ActWmf1Hdnh80tgVgUiJ3
A23: 2021 Q4 | B23: DEB_1.2 | C23: Dealing with student loan debt | D23: goal-debt-management | G23: topic-student-loans | H23: group-how-to-save | I23: profile-family-havekids profile-priorities-collegefund profile-priorities-debtmanagement | J23: https://www.figma.com/design/UOXktKMNWVxBSuZJhNGdyu/Goals?node-id=3508-49765&t=d6MHhwFJ4Ajl1iXH-1 | L23: class-low | O23: https://paven.io/content/article/6Eee9pQ3rSkCdLJnUBahVT
A24: 2021 Q4 | B24: DEB_1.3 | C24: How credit card debt works | D24: goal-debt-management | G24: topic-credit-cards, topic-resilience | H24: group-how-to-save | I24: profile-priorities-debtmanagement | J24: https://www.figma.com/design/UOXktKMNWVxBSuZJhNGdyu/Goals?node-id=3508-49766&t=d6MHhwFJ4Ajl1iXH-1 | L24: class-low | O24: https://paven.io/content/article/5hayL3vE1ypoDE8ELKcbtJ
A25: 2021 Q4 | B25: DEB_1.7 | C25: Credit scores 101 | D25: goal-debt-management | G25: topic-credit-score, topic-resilience | I25: profile-priorities-debtmanagement | J25: https://www.figma.com/design/UOXktKMNWVxBSuZJhNGdyu/Goals?node-id=3508-49771&t=d6MHhwFJ4Ajl1iXH-1 | L25: class-low | O25: https://paven.io/content/article/1NZMCPBnYrfE3v0M9fSXt4
A26: 2021 Q4 | B26: DEB_1.8 | C26: Track your debt payments | D26: goal-debt-management | G26: topic-bad-debt | H26: group-how-to-save | I26: profile-priorities-debtmanagement | J26: https://www.figma.com/design/UOXktKMNWVxBSuZJhNGdyu/Goals?node-id=3508-51036&t=d6MHhwFJ4Ajl1iXH-1 | L26: class-low | O26: https://paven.io/content/article/btv3P3YdkxNf0zqcwEAH4
A27: 2021 Q4 | B27: DEB_1.4 | C27: Tips to cut credit card debt | D27: goal-debt-management | G27: topic-credit-cards, topic-savviness | H27: group-how-to-save | I27: profile-priorities-debtmanagement | J27: https://www.figma.com/design/UOXktKMNWVxBSuZJhNGdyu/Goals?node-id=3508-49767&t=d6MHhwFJ4Ajl1iXH-1 | L27: class-mid | O27: https://paven.io/content/article/31poVSYMQMCbeM2FQofIRi
A28: 2021 Q4 | B28: RET_1.1 | C28: Retiring on your own terms | D28: goal-retirement | G28: topic-retirement | H28: group-priorities | I28: profile-family-myself profile-priorities-debtmanagement | J28: https://www.figma.com/design/UOXktKMNWVxBSuZJhNGdyu/Goals?node-id=3505-71716&t=d6MHhwFJ4Ajl1iXH-1 | L28: class-low | O28: https://paven.io/content/article/7vvkK5XEvXpA8tIDWNQlnH
A29: 2021 Q4 | B29: RET_1.2 | C29: Common barriers to saving | D29: goal-retirement | G29: topic-retirement, topic-401k | H29: group-how-to-save | I29: profile-goal-progress-never profile-goal-progress-yearly profile-goal-progress-quarterly profile-goal-progress-monthly profile-goal-progress-weekly profile-goal-progress-daily profile-priorities-debtmanagement | J29: https://www.figma.com/design/UOXktKMNWVxBSuZJhNGdyu/Goals?node-id=3506-7718&t=d6MHhwFJ4Ajl1iXH-1 | L29: class-low | O29: https://paven.io/content/article/1uEkmd8hDB1fPrHMXux21T
A30: 2021 Q4 | B30: RET_1.3 | C30: Define your target number | D30: goal-retirement | G30: topic-retirement, topic-401k | H30: group-priorities | I30: profile-goal-progress-never profile-goal-progress-yearly profile-goal-progress-quarterly profile-goal-progress-monthly profile-goal-progress-weekly profile-goal-progress-daily profile-priorities-debtmanagement | J30: https://www.figma.com/design/UOXktKMNWVxBSuZJhNGdyu/Goals?node-id=3506-15144&t=d6MHhwFJ4Ajl1iXH-1 | L30: class-low | O30: https://paven.io/content/article/7cSZtBYtkbyVT6P2o43ibs
A31: 2021 Q4 | B31: RET_1.4 | C31: Add your post-retirement work | D31: goal-retirement | G31: topic-retirement | H31: group-priorities | I31: profile-goal-progress-never profile-goal-progress-yearly profile-goal-progress-quarterly profile-goal-progress-monthly profile-goal-progress-weekly profile-goal-progress-daily profile-priorities-debtmanagement | J31: https://www.figma.com/design/UOXktKMNWVxBSuZJhNGdyu/Goals?node-id=3506-15653&t=d6MHhwFJ4Ajl1iXH-1 | L31: class-low | O31: https://paven.io/content/article/lwALm8GoRRB2UNy66fjhy
A32: 2021 Q4 | B32: RET_1.5 | C32: 401(k) basics | D32: goal-retirement | G32: topic-401k | H32: group-account-types | I32: profile-priorities-investing | J32: https://www.figma.com/design/UOXktKMNWVxBSuZJhNGdyu/Goals?node-id=3506-15654&t=d6MHhwFJ4Ajl1iXH-1 | L32: class-mid
A33: 2021 Q4 | B33: RET_1.8 | C33: Is a 401(k) loan a good option? | D33: goal-retirement | G33: topic-401k, topic-retirement | H33: group-account-types | I33: profile-priorities-investing | J33: https://www.figma.com/design/UOXktKMNWVxBSuZJhNGdyu/Goals?node-id=3506-15657&t=d6MHhwFJ4Ajl1iXH-1 | L33: class-low | O33: https://paven.io/content/article/1vdq8TQD1jqGJJvX3Wn53o
A34: 2021 Q4 | B34: LM_COM_1.4 | C34: Travel or save for emergencies? | D34: goal-emergency-fund | E34: lm-combining-finances | G34: topic-resilience | H34: group-how-to-save | I34: profile-priorities-debtmanagement profile-priorities-budgeting | J34: https://www.figma.com/design/kkMh7aGZkJopf7n5lbrrpX/Life-Moments?node-id=2565-19454&t=scW7PhQJA030oT78-1 | L34: class-low | O34: https://paven.io/content/article/4EdrGH95P0rcBrdli5jKXB
A35: 2021 Q4 | B35: LM_COM_1.5 | C35: Pay off debt or buy a home? | D35: goal-debt-management, goal-buying-a-home | E35: lm-combining-finances | G35: topic-resilience | H35: group-priorities | I35: profile-priorities-debtmanagement profile-priorities-budgeting | J35: https://www.figma.com/design/kkMh7aGZkJopf7n5lbrrpX/Life-Moments?node-id=2565-19455&t=scW7PhQJA030oT78-1 | L35: class-low | O35: https://paven.io/content/article/6JPHUAfF9TrK1IfGnXOu0i
A36: 2021 Q4 | B36: BAH_1.1 | C36: Ease your home buying concerns | D36: goal-buying-a-home | G36: topic-housing, topic-rent | H36: group-priorities | I36: profile-priorities-wanthome | L36: class-low | O36: https://paven.io/content/article/30CmxhE9d1pcdGvGaYSuId
A37: 2021 Q4 | B37: TF_1.1 | C37: Travel today and save for tomorrow | D37: goal-debt-management | G37: topic-travel | H37: group-priorities | I37: profile-priorities-debtmanagement profile-priorities-budgeting | J37: https://www.figma.com/design/UOXktKMNWVxBSuZJhNGdyu/Goals?node-id=3498-39610&t=d6MHhwFJ4Ajl1iXH-1 | L37: class-low | O37: https://paven.io/content/article/3ZweQAOsrsqgm28SCZF09Q
A38: 2021 Q4 | B38: TF_1.2 | C38: What kind of traveler are you? | G38: topic-travel | H38: group-priorities | I38: profile-priorities-debtmanagement profile-priorities-budgeting | J38: https://www.figma.com/design/UOXktKMNWVxBSuZJhNGdyu/Goals?node-id=3498-39611&t=d6MHhwFJ4Ajl1iXH-1 | L38: class-low | O38: https://paven.io/content/article/5YkoPnRVpjBLBo3WxrT37z
A39: 2021 Q4 | B39: TF_1.3 | C39: Travel fund strategies | D39: goal-debt-management | G39: topic-travel | H39: group-how-to-save | I39: profile-priorities-debtmanagement profile-priorities-budgeting | J39: https://www.figma.com/design/UOXktKMNWVxBSuZJhNGdyu/Goals?node-id=3498-39612&t=d6MHhwFJ4Ajl1iXH-1 | L39: class-low | O39: https://paven.io/content/article/7jBOX3g5w5ONNw06nvapin
A40: 2021 Q4 | B40: TF_1.4 | C40: Find like-minded travel companions | G40: topic-travel | H40: group-self-care | I40: profile-priorities-debtmanagement profile-priorities-budgeting | J40: https://www.figma.com/design/UOXktKMNWVxBSuZJhNGdyu/Goals?node-id=3498-39613&t=d6MHhwFJ4Ajl1iXH-1 | L40: class-low | O40: https://paven.io/content/article/h1TiRXpgSLIIVAiNuVqjF
...

Sheet Guidelines
A1: Article topic | B1: Group tag | C1: Topic tag | D1: Goal tag | E1: Class tag
A2: i.e. 401k | B2: group-account-types | C2: topic-401k | D2: goal-retirement
B3: group-priorities
B4: group-how-to-save
B5: group-self-care
B6: group-investing-strategies
B7: group-markets
B8: group-career
B9: group-monthly
B10: group-paven-app
B11: group-benefits

Sheet V2 New system worksheet
B1: Current ID | C1: Article title | D1: Goal (5) goal-retirement goal-emergency-fund goal-debt-management goal-kids-education goal-buying-a-home goal-buying-a-car | E1: Life Moment (5) lm-Inheritance lm-purposeful-learning lm-growing-your-family lm-combining-finances lm-relocation lm-covid | F1: Life Stage (3) -ls-early -ls-mid -ls-late | G1: Content topic (granular/specific) | H1: Secondary content topic (optional) | I1: Content group (overarching/adjacent) | J1: Profile profile-ownhome profile-wanthome profile-owncar profile-wantcar profile-spouse profile-havekids profile-wantkids profile-agingparents prorfile-havepets +more | K1: Level level-basic level-intermediate level-advanced | L1: Class (3) class-low class-mid class-high | M1: Relevant benefit for Suggestion | N1: Relevant action for Suggestion | O1: Next article in series for Suggestion | P1: Benefit | Q1: New life moment / goal ideas | R1: Notes
A2: Early Publications | B2: TT_1.4 | C2: Ways to use your pay raise | G2: topic-income | H2: topic-savviness | M2: =COUNTIF(G2:H188,N2) -> 7 | N2: {=_xlfn.UNIQUE(G2:G182)} -> topic-income | O2: {=_xlfn.UNIQUE(I2:I182)} -> 0 | P2: household-single | Q2: goal-wellbeing
A3: Early Publications | B3: LM_COM_1.4 | C3: Travel or save for emergencies | D3: goal-travel-fund goal-emergency-fund | E3: lm-combining-finances | G3: topic-resilience | I3: group-priorities | M3: =COUNTIF($G$2:$H$188,N3) -> 15 | N3: topic-resilience | O3: group-priorities | P3: household-teens | Q3: goal-paven
A4: Early Publications | B4: LM_COM_1.5 | C4: Pay off debt or buy a home? | D4: goal-debt-management goal-buying-a-home | E4: lm-combining-finances | G4: topic-resilience | I4: group-priorities | M4: =COUNTIF($G$2:$H$188,N4) -> 1 | N4: topic-relocation | O4: group-account-types
A5: Early Publications | B5: LM_RELO_1.1 | C5: Relocation 101 | E5: lm-relocation | G5: topic-relocation | I5: group-priorities | K5: level-basic | M5: =COUNTIF($G$2:$H$188,N5) -> 2 | N5: topic-car | O5: group-how-to-save
A6: Early Publications | B6: LM_RELO_1.2 | C6: Should I buy a car? | D6: goal-car | E6: lm-relocation | G6: topic-car | I6: group-priorities | M6: =COUNTIF($G$2:$H$188,N6) -> 1 | N6: topic-fsa | O6: group-self-care
A7: Early Publications | B7: LM_RELO_1.3 | C7: Save for emergencies or send money home? | D7: goal-emergency-fund goal-buying-a-home | E7: lm-growing-your-family lm-relocation | G7: topic-resilience | I7: group-priorities | M7: =COUNTIF($G$2:$H$188,N7) -> 10 | N7: topic-family | O7: group-investing-strategies
A8: Early Publications | B8: LM_RELO_1.5 | C8: Save for retirement or send money home? | D8: goal-retirement goal-buying-a-home | E8: lm-relocation | G8: topic-resilience | I8: group-priorities | M8: =COUNTIF($G$2:$H$188,N8) -> 2 | N8: topic-529 | O8: group-markets
A9: Early Publications | B9: EMF_1.1 | C9: Do I need an emergency fund? | D9: goal-emergency-fund | G9: topic-resilience | I9: group-priorities | M9: =COUNTIF($G$2:$H$188,N9) -> 2 | N9: topic-roth-ira | O9: group-career
A10: Early Publications | B10: EMF_1.2 | C10: Saving for the unknown | D10: goal-emergency-fund | G10: topic-resilience | I10: group-priorities | M10: =COUNTIF($G$2:$H$188,N10) -> 1 | N10: topic-brokerage | O10: group-monthly
A11: Early Publications | B11: EMF_1.3 | C11: Where to stash emergency funds | D11: goal-emergency-fund | G11: topic-resilience | I11: group-account-types | M11: =COUNTIF($G$2:$H$188,N11) -> 3 | N11: topic-bad-debt | O11: group-paven-app
A12: Early Publications | B12: FSA_2.1 | C12: How to make the most of your FSA | G12: topic-fsa | I12: group-account-types | M12: =COUNTIF($G$2:$H$188,N12) -> 2 | N12: topic-student-loans
A13: Early Publications | B13: EMF_1.5 | C13: Setting up automatic transfers | D13: goal-emergency-fund | G13: topic-resilience | I13: group-how-to-save | M13: =COUNTIF($G$2:$H$188,N13) -> 2 | N13: topic-credit-cards
A14: Early Publications | B14: EMF_1.6 | C14: How to boost emergency funds | D14: goal-emergency-fund | G14: topic-resilience | I14: group-how-to-save | M14: =COUNTIF($G$2:$H$188,N14) -> 1 | N14: topic-credit-score
A15: Early Publications | B15: SFC_1.1 | C15: 3 reasons to start saving now | D15: goal-kids-ed | G15: topic-family | I15: group-priorities | M15: =COUNTIF($G$2:$H$188,N15) -> 0 | N15: 0
A16: Early Publications | B16: SFC_1.2 | C16: Kids’ education vs other goals | D16: goal-kids-ed | G16: topic-family | I16: group-priorities | M16: =COUNTIF($G$2:$H$188,N16) -> 4 | N16: topic-retirement-planning
A17: Early Publications | B17: SFC_1.3 | C17: Education account types | D17: goal-kids-ed | G17: topic-family | I17: group-account-types | M17: =COUNTIF($G$2:$H$188,N17) -> 9 | N17: topic-401k
A18: Early Publications | B18: SFC_1.4 | C18: The 529 plan, explained | D18: goal-kids-ed | G18: topic-529 | I18: group-account-types | M18: =COUNTIF($G$2:$H$188,N18) -> 28 | N18: topic-benefits
A19: Early Publications | B19: SFC_1.5 | C19: Using a Roth IRA to save | D19: goal-kids-ed | G19: topic-roth-ira | I19: group-account-types | M19: =COUNTIF($G$2:$H$188,N19) -> 9 | N19: topic-travel
A20: Early Publications | B20: SFC_1.6 | C20: Using a brokerage account to save | D20: goal-kids-ed | G20: topic-brokerage | I20: group-account-types | M20: =COUNTIF($G$2:$H$188,N20) -> 15 | N20: topic-savviness
A21: Early Publications | B21: SFC_1.7 | C21: Other ways to save for education | D21: goal-kids-ed | G21: topic-family | I21: group-how-to-save | M21: =COUNTIF($G$2:$H$188,N21) -> 18 | N21: topic-stocks-bonds
A22: Early Publications | B22: MM_1.7 | C22: College coaching from Bright Horizons | D22: goal-kids-ed | G22: topic-family | H22: topic-benefits | M22: =COUNTIF($G$2:$H$188,N22) -> 4 | N22: topic-industries
A23: Early Publications | B23: DEB_1.1 | C23: Good debt vs bad debt | D23: goal-debt-management-management | G23: topic-bad-debt | I23: group-priorities | M23: =COUNTIF($G$2:$H$188,N23) -> 7 | N23: topic-volatility
A24: Early Publications | B24: DEB_1.2 | C24: Dealing with student loan debt | D24: goal-debt-management | G24: topic-student-loans | I24: group-how-to-save | M24: =COUNTIF($G$2:$H$188,N24) -> 5 | N24: topic-skills
A25: Early Publications | B25: DEB_1.3 | C25: How credit card debt works | D25: goal-debt-management | G25: topic-credit-cards | H25: topic-resilience | K25: level-basic | M25: =COUNTIF($G$2:$H$188,N25) -> 5 | N25: topic-side-hustle
A26: Early Publications | B26: DEB_1.4 | C26: Tips to cut credit card debt | D26: goal-debt-management | G26: topic-credit-cards | H26: topic-savviness | M26: =COUNTIF($G$2:$H$188,N26) -> 3 | N26: topic-hsa
A27: Early Publications | B27: DEB_1.5 | C27: Refinance your student loans | D27: goal-debt-management | G27: topic-student-loans | H27: topic-benefits | M27: =COUNTIF($G$2:$H$188,N27) -> 2 | N27: topic-financial-finesse
A28: Early Publications | B28: DEB_1.7 | C28: Credit scores 101 | D28: goal-debt-management | G28: topic-credit-score | H28: topic-resilience | K28: level-basic | M28: =COUNTIF($G$2:$H$188,N28) -> 4 | N28: topic-rsus
A29: Early Publications | B29: DEB_1.8 | C29: Track your debt payments | D29: goal-debt-management | G29: topic-bad-debt | I29: group-how-to-save | M29: =COUNTIF($G$2:$H$188,N29) -> 6 | N29: topic-taxes
A30: Early Publications | B30: RET_1.1 | C30: Retiring on your own terms | D30: goal-retirement | I30: group-priorities | M30: =COUNTIF($G$2:$H$188,N30) -> 3 | N30: topic-crypto
A31: Early Publications | B31: RET_1.2 | C31: Common barriers to saving | D31: goal-retirement | I31: group-how-to-save | M31: =COUNTIF($G$2:$H$188,N31) -> 5 | N31: topic-insurance
A32: Early Publications | B32: RET_1.3 | C32: Define your target number | D32: goal-retirement | I32: group-priorities | M32: =COUNTIF($G$2:$H$188,N32) -> 3 | N32: topic-estate-planning
A33: Early Publications | B33: RET_1.4 | C33: Add your post-retirement work | D33: goal-retirement | G33: topic-retirement-planning | I33: group-how-to-save | M33: =COUNTIF($G$2:$H$188,N33) -> 4 | N33: topic-first-home
A34: Early Publications | B34: RET_1.5 | C34: 401(k) basics | D34: goal-retirement | G34: topic-401k | I34: group-account-types | M34: =COUNTIF($G$2:$H$188,N34) -> 7 | N34: topic-inflation
A35: Early Publications | B35: RET_1.6 | C35: Your Fidelity 401(k) options | D35: goal-retirement | G35: topic-401k | H35: topic-benefits | M35: =COUNTIF($G$2:$H$188,N35) -> 5 | N35: topic-budget
A36: Early Publications | B36: RET_1.8 | C36: Is a 401(k) loan a good option? | D36: goal-retirement | G36: topic-401k | I36: group-account-types | M36: =COUNTIF($G$2:$H$188,N36) -> 7 | N36: topic-health
A37: Early Publications | B37: RET_1.10 | C37: The basics of Meta's 401(k) plan | D37: goal-retirement | G37: topic-401k | I37: group-account-types | M37: =COUNTIF($G$2:$H$188,N37) -> 4 | N37: topic-caregiving
A38: Early Publications | B38: GYF_1.1 | C38: Align your family's financial needs | E38: lm-growing-your-family lm-combining-finances | G38: topic-family | I38: group-priorities | M38: =COUNTIF($G$2:$H$188,N38) -> 7 | N38: topic-onboarding
A39: Early Publications | B39: GYF_1.9 | C39: Buying a home for your family | D39: goal-buying-a-home | E39: lm-growing-your-family lm-combining-finances | G39: topic-family | I39: group-priorities | M39: =COUNTIF($G$2:$H$188,N39) -> 3 | N39: topic-partner
A40: Early Publications | B40: GYF_1.10 | C40: Setting your kid up for future success | D40: goal-kids-ed | E40: lm-growing-your-family lm-combining-finances | G40: topic-family | I40: group-priorities | M40: =COUNTIF($G$2:$H$188,N40) -> 3 | N40: topic-inheritance
...

Sheet V1 New system worksheet
B1: Article title | C1: Goal (5) goal-retirement goal-emergency-fund goal-debt-management goal-kids-education goal-buying-a-home | D1: Life Moment (5) lm-Inheritance lm-purposeful-learning lm-growing-your-family lm-combining-finances lm-relocation lm-covid | E1: Life Stage (3) -ls-early -ls-mid -ls-late | F1: Content subject (granular/specific) | G1: Content family (overarching/adjacent) | I1: Class (3) class-low class-mid class-high | J1: New life moment / goal ideas | K1: Relevant benefit for Suggestion | L1: Relevant action for Suggestion | M1: Next article in series for Suggestion | N1: Level level-basic level-intermediate level-advanced | O1: Notes
B2: 401k limi updates 2024 | C2: goal-retirement | D2: NA | E2: NA | F2: topic-401k | G2: topic-retirement-accounts | J2: goal-car | K2: Schwab | L2: 401k vehicle setup | O2: We may want to be more granular on most popular topics, but more general on a low engagement topics
B3: IRA basics | C3: goal-retirement | D3: NA | E3: NA | F3: topic-IRA | G3: topic-retirement-accounts
B4: 529 basics | C4: goal-kids-education | D4: lm-growing your family | F4: topic-529 | G4: topic-kids
B5: Bonds | F5: Investing
F6: topics-bonds | G6: topic-investing
B7: Buying a car | C7: goal-car | G7: Crypto
B8: Side hustle | G8: RSU
F9: Family
C10: Kids ed | F10: Family
C11: Retirement
G12: Account types
D13: Retirement | G13: Account types
D14: Kids ed | G14: Account types
A17: Early Publications
A18: TT_1.4 | B18: Ways to use your pay raise | C18: goal-wellbeing | D18: lm-budgeting | E18: ls-all | F18: topic-pay-raise | G18: topic-income
A19: LM_COM_1.4 | B19: Travel or save for emergencies | C19: goal-travel-fund goal-emergency-fund | D19: lm-combining-finances | E19: ls-mid | F19: topic-spending | G19: topic-tradeoffs
A20: LM_COM_1.5 | B20: Pay off debt or buy a home? | C20: goal-debt goal-buying-a-home | D20: lm-combining-finances | E20: ls-mid | F20: topic-spending | G20: topic-tradeoffs
A21: LM_RELO_1.1 | B21: Relocation 101 | C21: goal-wellbeing | D21: lm-relocation | E21: ls-early | F21: topic-relocation | G21: topic-basics
A22: LM_RELO_1.2 | B22: Should I buy a car?
A23: LM_RELO_1.3 | B23: Save for emergencies or send money home?
A24: LM_RELO_1.5 | B24: Save for retirement or send money home?
A25: EMF_1.1 | B25: Do I need an emergency fund?
A26: EMF_1.2 | B26: Saving for the unknown
A27: EMF_1.3 | B27: Where to stash emergency funds
A28: FSA_2.1 | B28: How to make the most of your FSA
A29: EMF_1.5 | B29: Setting up automatic transfers
A30: EMF_1.6 | B30: How to boost emergency funds
A31: SFC_1.1 | B31: 3 reasons to start saving now
A32: SFC_1.2 | B32: Kids’ education vs other goals
A33: SFC_1.3 | B33: Education account types
... A38: MM_1.7 | B38: College coaching from Bright Horizons
A39: DEB_1.1 | B39: Good debt vs bad debt | C39: goal-debt | D39: lm-budgeting | E39: ls-early | F39: topic-debt | G39: topic-strategies
A40: DEB_1.2 | B40: Dealing with student loan debt | C40: goal-debt | D40: lm-student-loans | E40: ls-early | F40: topic-student-loans | G40: topic-strategies
A41: DEB_1.3 | B41: How credit card debt works | C41: goal-debt | D41: lm-budgeting | E41: ls-early | F41: topic-credit-cards | G41: topic-basics
A42: DEB_1.4 | B42: Tips to cut credit card debt | C42: goal-debt | D42: lm-budgeting | E42: ls-early | F42: topic-debt | G42: topic-strategies
A43: DEB_1.5 | B43: Refinance your student loans | C43: goal-debt | D43: lm-student-loans | E43: ls-early | F43: topic-debt | G43: topic-strategies
A44: DEB_1.6 | B44: Feeling overwhelmed? Get support
A45: DEB_1.7 | B45: Credit scores 101
A46: DEB_1.8 | B46: Track your debt payments
...

Sheet Sheet9
A1: TF_1.4 TF_1.8 SMINV_1.1 SMINV_1.4 SMINV_1.7 SMINV_1.8 SMINV_1.12 SMINV_1.13 SMINV_1.17 SMINV_1.18 SMINV_1.20 ES_1.4 SH_1.2 SH_1.4 HOME 1.4 CRY_1.1 LI_2.1 SMINV_2.1 BEN24_1.5 HSA_1.4 BAH_2.1 SMINV_2.6 SMINV_2.7 BEN23_1.10 SMINV_2.8 INH_2.1 GOAL_1.3 BEN23_2.6 GYF_2.3 Tax Refund_SIMULATOR BEN24_1.1 BEN24_1.2 FFTAX_1.1 TT24_1.3

Sheet Export of publications with tag
A1: title | B1: id | C1: identifier | D1: contentType | E1: date | F1: tags__001 | G1: tags__002 | H1: tags__003 | I1: tags__004 | J1: tags__005 | K1: tags__006 | L1: tags__007 | M1: tags__008 | N1: tags__009 | O1: tags__010 | P1: tags__011 | Q1: tags__012 | R1: tags__013 | S1: tags__014 | T1: tags__015 | U1: tags__016
A2: Caring for your parents with Wellthy | B2: 5ubss1n8Gur0R55hMiXIfS | C2: BEN23_2.4 | D2: exploreArticleCard | E2: 2023-08-22T21:46:44.689Z | F2: topic-caregiving | G2: benefit-wellthy
A3: How to set your first goal in Paven | B3: owseBAvFJG0YhuvrzfRpI | C3: GOAL_1.2 | D3: exploreArticleCard | E3: 2023-08-22T21:45:07.414Z | F3: topic-competing-goals | G3: topic-welcome
A4: New ways to save today | B4: 2uVkUsniZpnSL93XUw7D3N | C4: SMINV_3.3 | D4: exploreArticleCard | E4: 2023-08-22T18:10:09.450Z | F4: topic-smart-investing | G4: goal-smart-investing
A5: August: is it shrinkflation summer? | B5: 1IqFt8WpM4uacZfsTcGUiz | C5: TT23_1.8 | D5: exploreArticleCard | E5: 2023-08-11T22:26:55.696Z | F5: topic-inflation | G5: collection-timely-topics
A6: Caregiver benefits: get support with Meta | B6: 3KYnw2do1wxFB6Q1yqiXlb | C6: BEN23_2.3 | D6: exploreBenefitCard | E6: 2023-08-11T22:23:30.746Z | F6: topic-caregiving
A7: Inheritance: planning with care | B7: 1duNyvJJQXqpJzwPwiAgHa | C7: INH_2.1 | D7: exploreBenefitCard | E7: 2023-08-11T22:17:30.303Z | F7: topic-inheritance
A8: Meta’s estate planning benefit | B8: 2GsW4fbTdPK4dUzW0i2d7o | C8: EST_1.1 | D8: exploreBenefitCard | E8: 2023-08-11T21:21:25.137Z | F8: collection-meta-benefits
A9: Estate planning | B9: 694r5jryKhoDyV0sQnFLQy | C9: EST_vid_1 | D9: exploreVideoCard | E9: 2023-08-11T20:13:04.871Z | F9: benefit-estate-planning
A10: Planning for retirement beyond your 401(k) | B10: 6RCplWXPy3wJ3UMlPOBXr4 | C10: Occam's Razor 2023 | D10: simulatorContent | E10: 2023-08-09T12:13:47.759Z | F10: topic-retirement | G10: topic-401(k) | H10: topic-pre-tax-401(k) | I10: topic-roth-401(k) | J10: topic-after-tax-401(k) | K10: topic-ira | L10: topic-roth-ira | M10: topic-account-types | N10: topic-401 | O10: topic-401k | P10: collection-401(k)-retirement | Q10: collection-401(k)-withdrawals-retirement | R10: collection-retirement
A11: Meta life insurance: cover your loved ones | B11: KqhuSFoODJlrEVoBt3Eqa | C11: LI_2.1 | D11: exploreBenefitCard | E11: 2023-08-08T18:47:32.692Z | F11: Life Insurance- topic | G11: Life Insurance - collection | H11: collection-meta-benefits
A12: Investing in the future of health | B12: 5i9cosAfHxAXEfBxaIez5m | C12: SMINV_3.2 | D12: exploreArticleCard | E12: 2023-08-04T19:37:31.037Z | F12: topic-smart-investing | G12: topic-health | H12: topic-stock
A13: Investors: ready for a fresh start? | B13: 1PwhRz7nlEZzy689dD2r4m | C13: SMINV_3.1 | D13: exploreArticleCard | E13: 2023-07-28T22:01:57.710Z | F13: topic-smart-investing | G13: topic-stock
A14: Sharing your money – it’s a life moment | B14: UvrcaNa1cwMe969OptsKb | C14: LM_COM_2.1 | D14: exploreArticleCard | E14: 2023-07-28T22:01:15.655Z | F14: topic-combining-finances | G14: lm-combining-finances
A15: Ways to combine your finances | B15: 46hjcn1OzNf5GE3haVHqNg | C15: LM_COM_1.1 | D15: exploreArticleCard | E15: 2023-07-28T00:43:13.695Z | F15: topic-combining-finances | G15: lm-combining-finances | H15: story-combining-finances | I15: collection-goals-101 | J15: collection-combining-finances
A16: Goals: What are they? Why do they matter? | B16: fufOxWn3qSC6N8lCPEArb | C16: GOAL_1.1 | D16: exploreArticleCard | E16: 2023-07-25T22:33:55.940Z | F16: topic-competing-goals | G16: collection-goals-101
A17: Caring for teens with Cleo | B17: 1t7PMBzjZvmyyMBNqIwe5O | C17: BEN23_2.2 | D17: exploreBenefitCard | E17: 2023-07-25T22:31:50.972Z | F17: topic-kids-education | G17: topic-growing-your-family
A18: Is now a good time to invest? | B18: 6c21mg94YY9xqv3xNRCF6b | C18: SMINV_1.9 | D18: exploreArticleCard | E18: 2023-07-21T19:56:29.201Z | F18: topic-smart-investing | G18: Smart investing - collection
A19: How to make money in a downturn market | B19: 27qsF992ZH4QiAcAhG2dOB | C19: SMINV_1.12 | D19: exploreArticleCard | E19: 2023-07-21T19:46:50.038Z | F19: topic-smart-investing | G19: Smart investing - collection
A20: Market volatility: How to navigate | B20: 4AVBAIJEUPBkrXOgCyHhGC | C20: SMINV_1.11 | D20: exploreArticleCard | E20: 2023-07-21T19:45:56.099Z | F20: topic-smart-investing | G20: Smart investing - collection
A21: Can you time the market? | B21: 10hEZDS9HPFQI88Dy49DTh | C21: SMINV_1.10 | D21: exploreArticleCard | E21: 2023-07-21T19:45:37.766Z | F21: topic-smart-investing | G21: Smart investing - collection
A22: Why should you invest? | B22: 3q3tsXFp5W4eSMo4yFGXJh | C22: SMINV_1.8 | D22: exploreArticleCard | E22: 2023-07-21T19:44:48.953Z | F22: topic-smart-investing | G22: Smart investing - collection
A23: Define your target number | B23: 7cSZtBYtkbyVT6P2o43ibs | C23: RET_1.3 | D23: exploreArticleCard | E23: 2023-07-21T19:39:34.515Z | F23: topic-retirement | G23: goal-retirement | H23: collection-vision-retirement | I23: collection-retirement | J23: collection-build-vision
A24: Common barriers to saving | B24: 1uEkmd8hDB1fPrHMXux21T | C24: RET_1.2 | D24: exploreArticleCard | E24: 2023-07-21T19:39:06.623Z | F24: topic-retirement | G24: goal-retirement | H24: story-retirement | I24: collection-retirement
A25: Retiring on your own terms | B25: 7vvkK5XEvXpA8tIDWNQlnH | C25: RET_1.1 | D25: exploreArticleCard | E25: 2023-07-21T19:38:22.974Z | F25: topic-retirement | G25: goal-retirement | H25: collection-vision-retirement | I25: collection-retirement
A26: 401(k) basics | B26: FFeCJfv5l1vOMoK7jPcKg | C26: RET_1.5 | D26: exploreArticleCard | E26: 2023-07-21T19:35:48.966Z | F26: topic-retirement | G26: topic-401(k) | H26: topic-401 | I26: topic-401k | J26: goal-retirement | K26: collection-vision-retirement | L26: collection-retirement
A27: Is a 401(k) loan a good option? | B27: 1vdq8TQD1jqGJJvX3Wn53o | C27: RET_1.8 | D27: exploreArticleCard | E27: 2023-07-21T19:35:14.048Z | F27: topic-retirement | G27: topic-401(k) | H27: topic-loans | I27: topic-401 | J27: topic-401k | K27: goal-retirement | L27: collection-401(k)-withdrawals-retirement | M27: collection-retirement
A28: Your Fidelity 401(k) options | B28: 37K6qv3YXJWe5lc4geHKqv | C28: RET_1.6 | D28: exploreBenefitCard | E28: 2023-07-21T19:34:11.410Z | F28: topic-retirement | G28: topic-401 | H28: topic-401k | I28: goal-retirement | J28: story-retirement | K28: benefit-fidelity-401(k)
A29: 401(k) news: friend or foe? | B29: 7lFtpVjgylBO9lWx6xsLkf | C29: BEN23_1.3 | D29: exploreArticleCard | E29: 2023-07-21T19:09:03.389Z | F29: topic-retirement | G29: topic-401(k) | H29: topic-401 | I29: topic-401k | J29: collection-meta-benefits
A30: New 401(k) and IRA maxes for 2023 | B30: 5xjza1fH94s5LckPzkl6VD | C30: RET_1.11 | D30: exploreArticleCard | E30: 2023-07-21T19:07:17.249Z | F30: topic-retirement | G30: topic-401(k) | H30: topic-ira | I30: topic-roth-ira | J30: topic-401 | K30: topic-match
A31: Small steps to a healthier future | B31: 2n6ebhc1JmSHRjq1hlqEAc | C31: BEN23_2.1 | D31: exploreBenefitCard | E31: 2023-07-17T19:57:36.293Z | F31: topic-mental-health | G31: topic-health
A32: July: recharge with self-care | B32: 40VkV7JkiFDi95pLlBpt1A | C32: TT23_1.7 | D32: exploreArticleCard | E32: 2023-07-17T19:53:32.572Z | F32: topic-health
A33: Feeling overwhelmed? Get support from Lyra | B33: 4EsmZO7BgpndMdnjSkEEzo | C33: DEB_1.6 | D33: exploreBenefitCard | E33: 2023-07-10T23:02:30.493Z | F33: topic-debt | G33: topic-lyra | H33: goal-debt-management | I33: benefit-lyra-mental-health | J33: benefit-people-portal | K33: collection-meta-benefits
A34: Stocks: how to find the real value | B34: 6AgPLGxufTjPh3N8GCYbLb | C34: SMINV_2.9 | D34: exploreArticleCard | E34: 2023-07-10T19:59:21.018Z | F34: topic-smart-investing | G34: topic-stock
A35: Spending too little, saving too much? | B35: 3VO3MiHsCUD5Ohyz42yD5K | C35: EMF_2.2 | D35: exploreArticleCard | E35: 2023-07-10T19:57:50.894Z | F35: topic-savings-account
A36: What’s the move in AI? | B36: 3jHoKvOolfJqWtewpEDxV | C36: SMINV_2.10 | D36: exploreArticleCard | E36: 2023-07-10T19:55:56.000Z | F36: topic-smart-investing | G36: topic-stock
A37: Estate planning for everyone | B37: 6LItN1K4USGOcLBAoJkV1K | C37: EST_1.3 | D37: exploreArticleCard | E37: 2023-07-10T19:54:13.723Z | F37: benefit-estate-planning
A38: Investing practice: how to manage market risk | B38: 3fwrSLeQqao4pZHzCSYOGZ | C38: Entry Point Simulator | D38: simulatorContent | E38: 2023-07-10T15:11:26.765Z | F38: topic-smart-investing | G38: topic-stock
A39: 401(k) conversions: how they work | B39: 7gq8ye9mIQBOlSNZ4mGz8u | C39: BEN23_1.10 | D39: exploreBenefitCard | E39: 2023-07-07T13:49:20.296Z | F39: topic-401(k) | G39: topic-roth-ira | H39: topic-401 | I39: topic-401k
A40: Buying a car: what to know | B40: 7oATLbHlAL221cMeVUAoy6 | C40: LM_RELO_1.2 | D40: exploreArticleCard | E40: 2023-07-06T18:33:44.675Z | F40: topic-relocation | G40: lm-relocation | H40: collection-relocating
...

Sheet Count of Unique tags
A1: Investing | B1: topic-smart-investing | E1: =COUNTIF('Export of publications with tag'!$F$2:$U$197,B1) -> 42
A2: Investing | B2: Smart investing - collection | C2: topic-stock | D2: topic-smart-investing | E2: =COUNTIF('Export of publications with tag'!$F$2:$U$197,B2) -> 22
A3: Investing | B3: topic-stock | E3: =COUNTIF('Export of publications with tag'!$F$2:$U$197,B3) -> 17
A4: Debt | B4: topic-debt | E4: =COUNTIF('Export of publications with tag'!$F$2:$U$197,B4) -> 17
A5: Benefits | B5: collection-meta-benefits | C5: collection-fb-benefits | E5: =COUNTIF('Export of publications with tag'!$F$2:$U$197,B5) -> 16 | F5: duplicates
A6: Retirement | B6: topic-retirement | E6: =COUNTIF('Export of publications with tag'!$F$2:$U$197,B6) -> 16
A7: Housing | B7: collection-buying-a-home | E7: =COUNTIF('Export of publications with tag'!$F$2:$U$197,B7) -> 15
A8: Housing | B8: goal-buying-a-home | E8: =COUNTIF('Export of publications with tag'!$F$2:$U$197,B8) -> 15
A9: Housing | B9: topic-housing | E9: =COUNTIF('Export of publications with tag'!$F$2:$U$197,B9) -> 14
A10: Family | B10: topic-growing-your-family | E10: =COUNTIF('Export of publications with tag'!$F$2:$U$197,B10) -> 13
A11: Family | B11: lm-growing-your-family | E11: =COUNTIF('Export of publications with tag'!$F$2:$U$197,B11) -> 12
A12: Emergency fund | B12: topic-emergency-fund | E12: =COUNTIF('Export of publications with tag'!$F$2:$U$197,B12) -> 12
A13: Retirement | B13: collection-retirement | E13: =COUNTIF('Export of publications with tag'!$F$2:$U$197,B13) -> 11
A14: Markets | B14: topic-inflation | E14: =COUNTIF('Export of publications with tag'!$F$2:$U$197,B14) -> 11
A15: Debt | B15: goal-debt-management | E15: =COUNTIF('Export of publications with tag'!$F$2:$U$197,B15) -> 10
A16: Account types | B16: topic-401 | E16: =COUNTIF('Export of publications with tag'!$F$2:$U$197,B16) -> 10
A17: Account types | B17: topic-401(k) | C17: topic-401 | D17: topic-401k | E17: =COUNTIF('Export of publications with tag'!$F$2:$U$197,B17) -> 10
A18: Budget - Extras | B18: topic-travel | C18: collection-travel-fund | E18: =COUNTIF('Export of publications with tag'!$F$2:$U$197,B18) -> 10
A19: Kids Education | B19: topic-kids-education | E19: =COUNTIF('Export of publications with tag'!$F$2:$U$197,B19) -> 10
A20: Debt | B20: collection-debt | E20: =COUNTIF('Export of publications with tag'!$F$2:$U$197,B20) -> 9
A21: App | B21: collection-goals-101 | E21: =COUNTIF('Export of publications with tag'!$F$2:$U$197,B21) -> 9
A22: Kids Education | B22: collection-kids-education | E22: =COUNTIF('Export of publications with tag'!$F$2:$U$197,B22) -> 9
A23: Account types | B23: topic-401k | E23: =COUNTIF('Export of publications with tag'!$F$2:$U$197,B23) -> 9
A24: Budget - Extras | B24: topic-travel-fund | E24: =COUNTIF('Export of publications with tag'!$F$2:$U$197,B24) -> 9
A25: App | B25: collection-timely-topics | E25: =COUNTIF('Export of publications with tag'!$F$2:$U$197,B25) -> 9
A26: Family | B26: collection-growing-your-family | E26: =COUNTIF('Export of publications with tag'!$F$2:$U$197,B26) -> 8
A27: Debt | B27: collection-managing-debt | E27: =COUNTIF('Export of publications with tag'!$F$2:$U$197,B27) -> 8
A28: Budget - Extras | B28: collection-travel-fund | E28: =COUNTIF('Export of publications with tag'!$F$2:$U$197,B28) -> 8
A29: Retirement | B29: goal-retirement | E29: =COUNTIF('Export of publications with tag'!$F$2:$U$197,B29) -> 8
A30: Budget - Extras | B30: goal-saving-for-travel | E30: =COUNTIF('Export of publications with tag'!$F$2:$U$197,B30) -> 8
... A49: Benefits | B49: topic-match | E49: =COUNTIF('Export of publications with tag'!$F$2:$U$197,B49) -> 5
A50: Income | B50: topic-rsu | C50: topic-restricted | D50: topic-rsus | E50: =COUNTIF('Export of publications with tag'!$F$2:$U$197,B50) -> 5
A51: Income | B51: topic-starting-side-hustle | E51: =COUNTIF('Export of publications with tag'!$F$2:$U$197,B51) -> 5
A52: Account types | B52: topic-hsa | E52: =COUNTIF('Export of publications with tag'!$F$2:$U$197,B52) -> 5
A53: Account types | B53: topic-roth-ira | E53: =COUNTIF('Export of publications with tag'!$F$2:$U$197,B53) -> 5
A54: Budget | B54: topic-budget | E54: =COUNTIF('Export of publications with tag'!$F$2:$U$197,B54) -> 5
A55: ?? | B55: topic-relocation | E55: =COUNTIF('Export of publications with tag'!$F$2:$U$197,B55) -> 5
A56: App | B56: topic-welcome | E56: =COUNTIF('Export of publications with tag'!$F$2:$U$197,B56) -> 5
A57: Income | B57: topic-side-hustle | E57: =COUNTIF('Export of publications with tag'!$F$2:$U$197,B57) -> 5
A58: Account types | B58: benefit-fidelity-401(k) | E58: =COUNTIF('Export of publications with tag'!$F$2:$U$197,B58) -> 4
...

Sheet Experiment - Topics->Tags
A1: Wealth strategies | B1: {=_xlfn.UNIQUE('Count of Unique tags'!A1:A133)} -> Investing | C1: =COUNTIF('Count of Unique tags'!A1:A133,B1) -> 5
B2: Debt | C2: =COUNTIF('Count of Unique tags'!A2:A134,B2) -> 5
A3: Benefits | B3: Benefits | C3: =COUNTIF('Count of Unique tags'!A3:A135,B3) -> 7
B4: Retirement | C4: =COUNTIF('Count of Unique tags'!A4:A136,B4) -> 6
B5: Housing | C5: =COUNTIF('Count of Unique tags'!A5:A137,B5) -> 5
B6: Family | C6: =COUNTIF('Count of Unique tags'!A6:A138,B6) -> 5 | D6: Couples
A7: Security | B7: Emergency fund | C7: =COUNTIF('Count of Unique tags'!A7:A139,B7) -> 4
B8: Markets | C8: =COUNTIF('Count of Unique tags'!A8:A140,B8) -> 1 | D8: ??
A9: Wealth strategies | B9: Account types | C9: =COUNTIF('Count of Unique tags'!A9:A141,B9) -> 22 | D9: break up?
A10: Gratification | B10: Budget - Extras | C10: =COUNTIF('Count of Unique tags'!A10:A142,B10) -> 4
B11: Kids Education | C11: =COUNTIF('Count of Unique tags'!A11:A143,B11) -> 5 | D11: ??
B12: App | C12: =COUNTIF('Count of Unique tags'!A12:A144,B12) -> 5
A13: Wealth strategies | B13: Taxes | C13: =COUNTIF('Count of Unique tags'!A13:A145,B13) -> 3
